<?xml version="1.0"?>
<robot name="1100331_robot">

  <!-- base_link -->
  <link name="base_link">
    <visual>
      <geometry><box size="0.4 0.3 0.1"/></geometry>
      <material name="gray"><color rgba="0.6 0.6 0.6 1"/></material>
    </visual>
    <collision><geometry><box size="0.4 0.3 0.1"/></geometry></collision>
    <inertial>
      <mass value="5.0"/>
      <origin xyz="0 0 0" rpy="0 0 0"/>
      <inertia ixx="0.1" ixy="0.0" ixz="0.0" iyy="0.1" iyz="0.0" izz="0.1"/>
    </inertial>
  </link>

  <!-- left wheel -->
  <link name="left_wheel_link">
    <visual><origin rpy="1.5708 0 0"/><geometry><cylinder radius="0.05" length="0.02"/></geometry></visual>
    <collision><origin rpy="1.5708 0 0"/><geometry><cylinder radius="0.05" length="0.02"/></geometry></collision>
    <inertial><mass value="0.2"/><inertia ixx="0.001" ixy="0.0" ixz="0.0" iyy="0.001" iyz="0.0" izz="0.001"/></inertial>
  </link>
  <joint name="left_wheel_joint" type="continuous">
    <parent link="base_link"/>
    <child link="left_wheel_link"/>
    <origin xyz="0 0.16 0.0" rpy="0 0 0"/>
    <axis xyz="0 1 0"/>
  </joint>

  <!-- right wheel -->
  <link name="right_wheel_link">
    <visual><origin rpy="1.5708 0 0"/><geometry><cylinder radius="0.05" length="0.02"/></geometry></visual>
    <collision><origin rpy="1.5708 0 0"/><geometry><cylinder radius="0.05" length="0.02"/></geometry></collision>
    <inertial><mass value="0.2"/><inertia ixx="0.001" ixy="0.0" ixz="0.0" iyy="0.001" iyz="0.0" izz="0.001"/></inertial>
  </link>
  <joint name="right_wheel_joint" type="continuous">
    <parent link="base_link"/>
    <child link="right_wheel_link"/>
    <origin xyz="0 -0.16 0.0" rpy="0 0 0"/>
    <axis xyz="0 1 0"/>
  </joint>

  <!-- lidar -->
  <link name="lidar_link">
    <visual><geometry><cylinder length="0.05" radius="0.03"/></geometry></visual>
    <collision><geometry><cylinder length="0.05" radius="0.03"/></geometry></collision>
    <inertial><mass value="0.1"/><inertia ixx="0.001" ixy="0.0" ixz="0.0" iyy="0.001" iyz="0.0" izz="0.001"/></inertial>
  </link>
  <joint name="lidar_joint" type="fixed">
    <parent link="base_link"/>
    <child link="lidar_link"/>
    <origin xyz="0 0 0.1" rpy="0 0 0"/>
  </joint>

  <!-- camera -->
  <link name="camera_link">
    <visual><geometry><box size="0.05 0.05 0.05"/></geometry></visual>
    <collision><geometry><box size="0.05 0.05 0.05"/></geometry></collision>
    <inertial><mass value="0.2"/><inertia ixx="0.01" ixy="0.0" ixz="0.0" iyy="0.01" iyz="0.0" izz="0.01"/></inertial>
  </link>
  <joint name="camera_joint" type="fixed">
    <parent link="base_link"/>
    <child link="camera_link"/>
    <origin xyz="0.1 0 0.1" rpy="0 0 0"/>
  </joint>

  <!-- shoulder -->
  <link name="shoulder_link">
    <visual><geometry><cylinder length="0.05" radius="0.03"/></geometry></visual>
    <collision><geometry><cylinder length="0.05" radius="0.03"/></geometry></collision>
    <inertial><mass value="0.2"/><inertia ixx="0.01" ixy="0.0" ixz="0.0" iyy="0.01" iyz="0.0" izz="0.01"/></inertial>
  </link>
  <joint name="shoulder_joint" type="revolute">
    <parent link="base_link"/>
    <child link="shoulder_link"/>
    <origin xyz="0 0 0.15" rpy="0 0 0"/>
    <axis xyz="0 1 0"/>
    <limit lower="-1.57" upper="1.57" effort="1" velocity="1"/>
  </joint>

  <!-- elbow -->
  <link name="elbow_link">
    <visual><geometry><cylinder length="0.15" radius="0.02"/></geometry></visual>
    <collision><geometry><cylinder length="0.15" radius="0.02"/></geometry></collision>
    <inertial><mass value="0.2"/><inertia ixx="0.01" ixy="0.0" ixz="0.0" iyy="0.01" iyz="0.0" izz="0.01"/></inertial>
  </link>
  <joint name="elbow_joint" type="revolute">
    <parent link="shoulder_link"/>
    <child link="elbow_link"/>
    <origin xyz="0 0 0.1" rpy="0 0 0"/>
    <axis xyz="0 1 0"/>
    <limit lower="-1.57" upper="1.57" effort="1" velocity="1"/>
  </joint>

    <!-- Gripper base -->
  <link name="gripper_base">
    <visual><geometry><box size="0.02 0.08 0.02"/></geometry></visual>
    <collision><geometry><box size="0.02 0.08 0.02"/></geometry></collision>
    <inertial>
      <mass value="0.05"/>
      <inertia ixx="1e-5" iyy="1e-5" izz="1e-5" ixy="0.0" ixz="0.0" iyz="0.0"/>
    </inertial>
  </link>
  <joint name="gripper_base_joint" type="fixed">
    <parent link="elbow_link"/>
    <child link="gripper_base"/>
    <origin xyz="0 0 0.1" rpy="0 0 0"/>
  </joint>

  <!-- Left finger -->
  <link name="left_finger">
    <visual><geometry><box size="0.01 0.04 0.01"/></geometry></visual>
    <collision><geometry><box size="0.01 0.04 0.01"/></geometry></collision>
    <inertial>
      <mass value="0.01"/>
      <inertia ixx="1e-5" iyy="1e-5" izz="1e-5" ixy="0.0" ixz="0.0" iyz="0.0"/>
    </inertial>
  </link>
  <joint name="left_finger_joint" type="revolute">
    <parent link="gripper_base"/>
    <child link="left_finger"/>
    <origin xyz="0 0.04 0" rpy="0 0 0"/>
    <axis xyz="0 0 1"/>
    <limit lower="0" upper="0.6" effort="5" velocity="1.0"/>
  </joint>

  <!-- Right finger -->
  <link name="right_finger">
    <visual><geometry><box size="0.01 0.04 0.01"/></geometry></visual>
    <collision><geometry><box size="0.01 0.04 0.01"/></geometry></collision>
    <inertial>
      <mass value="0.01"/>
      <inertia ixx="1e-5" iyy="1e-5" izz="1e-5" ixy="0.0" ixz="0.0" iyz="0.0"/>
    </inertial>
  </link>
  <joint name="right_finger_joint" type="revolute">
    <parent link="gripper_base"/>
    <child link="right_finger"/>
    <origin xyz="0 -0.04 0" rpy="0 0 0"/>
    <axis xyz="0 0 -1"/>
    <limit lower="0" upper="0.6" effort="5" velocity="1.0"/>
  </joint>

  <!-- Gazebo Plugin for Joint Controllers -->
  <gazebo>
  <plugin name="diff_drive_controller" filename="libgazebo_ros_diff_drive.so">
    <leftJoint>left_wheel_joint</leftJoint>
    <rightJoint>right_wheel_joint</rightJoint>
    ...
  </plugin>
</gazebo>
</robot>

